Traceback (most recent call last):
  File "C:\Users\Asus\AppData\Local\Packages\PythonSoftwareFoundation.Python.3.11_qbz5n2kfra8p0\LocalCache\local-packages\Python311\site-packages\jupyter_cache\executors\utils.py", line 58, in single_nb_execution
    executenb(
  File "C:\Users\Asus\AppData\Local\Packages\PythonSoftwareFoundation.Python.3.11_qbz5n2kfra8p0\LocalCache\local-packages\Python311\site-packages\nbclient\client.py", line 1319, in execute
    return NotebookClient(nb=nb, resources=resources, km=km, **kwargs).execute()
           ^^^^^^^^^^^^^^^^^^^^^^^^^^^^^^^^^^^^^^^^^^^^^^^^^^^^^^^^^^^^^^^^^^^^^
  File "C:\Users\Asus\AppData\Local\Packages\PythonSoftwareFoundation.Python.3.11_qbz5n2kfra8p0\LocalCache\local-packages\Python311\site-packages\jupyter_core\utils\__init__.py", line 165, in wrapped
    return loop.run_until_complete(inner)
           ^^^^^^^^^^^^^^^^^^^^^^^^^^^^^^
  File "C:\Program Files\WindowsApps\PythonSoftwareFoundation.Python.3.11_3.11.2544.0_x64__qbz5n2kfra8p0\Lib\asyncio\base_events.py", line 654, in run_until_complete
    return future.result()
           ^^^^^^^^^^^^^^^
  File "C:\Users\Asus\AppData\Local\Packages\PythonSoftwareFoundation.Python.3.11_qbz5n2kfra8p0\LocalCache\local-packages\Python311\site-packages\nbclient\client.py", line 709, in async_execute
    await self.async_execute_cell(
  File "C:\Users\Asus\AppData\Local\Packages\PythonSoftwareFoundation.Python.3.11_qbz5n2kfra8p0\LocalCache\local-packages\Python311\site-packages\nbclient\client.py", line 1062, in async_execute_cell
    await self._check_raise_for_error(cell, cell_index, exec_reply)
  File "C:\Users\Asus\AppData\Local\Packages\PythonSoftwareFoundation.Python.3.11_qbz5n2kfra8p0\LocalCache\local-packages\Python311\site-packages\nbclient\client.py", line 918, in _check_raise_for_error
    raise CellExecutionError.from_cell_and_msg(cell, exec_reply_content)
nbclient.exceptions.CellExecutionError: An error occurred while executing the following cell:
------------------
from ucimlrepo import fetch_ucirepo 
  
# fetch dataset 
predict_students_dropout_and_academic_success = fetch_ucirepo(id=697) 
  
# data (as pandas dataframes) 
X = predict_students_dropout_and_academic_success.data.features 
y = predict_students_dropout_and_academic_success.data.targets 
  
# metadata 
print(predict_students_dropout_and_academic_success.metadata) 
  
# variable information 
print(predict_students_dropout_and_academic_success.variables) 

------------------


[31m---------------------------------------------------------------------------[39m
[31mModuleNotFoundError[39m                       Traceback (most recent call last)
[36mCell[39m[36m [39m[32mIn[2][39m[32m, line 1[39m
[32m----> [39m[32m1[39m [38;5;28;01mfrom[39;00m[38;5;250m [39m[34;01mucimlrepo[39;00m[38;5;250m [39m[38;5;28;01mimport[39;00m fetch_ucirepo 
[32m      3[39m [38;5;66;03m# fetch dataset [39;00m
[32m      4[39m predict_students_dropout_and_academic_success = fetch_ucirepo([38;5;28mid[39m=[32m697[39m) 

[31mModuleNotFoundError[39m: No module named 'ucimlrepo'

